<?xml version="1.0" ?>
<robot name="push-stick" xmlns:xacro="http://ros.org/wiki/xacro">
    <link name="wrist_3_link">
        <visual>
            <geometry>
                <mesh filename="visual/wrist3.stl"/>
            </geometry>
        </visual>
        <collision>
            <geometry>
                <mesh filename="collision/wrist3.stl"/>
            </geometry>
        </collision>
        <inertial>
            <mass value="0.1879"/>
            <origin rpy="0 0 0" xyz="0.0 0.0 0.0"/>
            <inertia ixx="0.0171364731454" ixy="0.0" ixz="0.0" iyy="0.0171364731454" iyz="0.0" izz="0.033822"/>
        </inertial>
    </link>

    <link name="tool0"/>

    <link name="panda_hand">
        <visual>
            <geometry>
                <mesh filename="visual/hand-3.obj"/>
            </geometry>
        </visual>
        <collision>
            <geometry>
                <mesh filename="collision/hand.obj"/>
            </geometry>
        </collision>
        <inertial>
            <mass value="0.73"/>
            <origin rpy="0 0 0" xyz="-0.01 0.0 0.03"/>
            <inertia ixx="0.001" ixy="0.0" ixz="0.0" iyy="0.0025" iyz="0.0" izz="0.0017"/>
        </inertial>
    </link>

    <joint name="wrist_3_link-tool0_fixed_joint" type="fixed">
        <origin rpy="-1.57079632679 0 0" xyz="0 0.0823 0"/>
        <parent link="wrist_3_link"/>
        <child link="tool0"/>
    </joint>

    <joint name="hand_joint" type="prismatic">
        <origin rpy="0 0 -1.570796326948966" xyz="0 0 0.01"/>
        <parent link="tool0"/>
        <child link="panda_hand"/>
        <axis xyz="0 0 1"/>
        <dynamics damping="10.0"/>
        <limit effort="20" lower="0.0" upper="1.0" velocity="1.0"/>
    </joint>

</robot>
